Workbook
Name Customer: #REF!
Name Customers: #REF!
Name Product: Orders!$I:$I
Name Slicer_Brand: #N/A
Name Slicer_Category: #N/A
Name Slicer_City: #N/A
Name Slicer_Order_Date__Month: #N/A

Sheet Customers
A1: Customer_ID | B1: Customer_Name | C1: City | D1: Phone_Number | E1: Email
A2: 1 | B2: Mohammed Ali | C2: Jeddah | D2: 9665302440 | E2: =B2&"@Ex.com" -> Mohammed Ali@Ex.com
A3: 2 | B3: Mona Salah | C3: Riyadh | D3: 9664576801 | E3: =B3&"@Ex.com" -> Mona Salah@Ex.com
A4: 3 | B4: Turky Abdullah | C4: Al Dammam | D4: 9663461201 | E4: =B4&"@Ex.com" -> Turky Abdullah@Ex.com
A5: 4 | B5: Sara Khalid | C5: Makkah | D5: 9662605575 | E5: =B5&"@Ex.com" -> Sara Khalid@Ex.com
A6: 5 | B6: Omar Hassan | C6: Jeddah | D6: 9.661685e+09 | E6: =B6&"@Ex.com" -> Omar Hassan@Ex.com
A7: 6 | B7: Noor Abdullah | C7: Riyadh | D7: 9665302440 | E7: =B7&"@Ex.com" -> Noor Abdullah@Ex.com | G7: =COUNTA(A:A) -> 151
A8: 7 | B8: Faisal Mohammed | C8: Al Dammam | D8: 9664576801 | E8: =B8&"@Ex.com" -> Faisal Mohammed@Ex.com
A9: 8 | B9: Aisha Saeed | C9: Makkah | D9: 9663461201 | E9: =B9&"@Ex.com" -> Aisha Saeed@Ex.com
A10: 9 | B10: Khaled Ibrahim | C10: Jeddah | D10: 9662605575 | E10: =B10&"@Ex.com" -> Khaled Ibrahim@Ex.com
A11: 10 | B11: Lina Abdulrahman | C11: Riyadh | D11: 9.661685e+09 | E11: =B11&"@Ex.com" -> Lina Abdulrahman@Ex.com
A12: 11 | B12: Youssef Nasser | C12: Al Dammam | D12: 9665302440 | E12: =B12&"@Ex.com" -> Youssef Nasser@Ex.com
A13: 12 | B13: Huda Saleh | C13: Makkah | D13: 9664576801 | E13: =B13&"@Ex.com" -> Huda Saleh@Ex.com
A14: 13 | B14: Ahmed Faris | C14: Jeddah | D14: 9663461201 | E14: =B14&"@Ex.com" -> Ahmed Faris@Ex.com
A15: 14 | B15: Reem Adel | C15: Riyadh | D15: 9662605575 | E15: =B15&"@Ex.com" -> Reem Adel@Ex.com
A16: 15 | B16: Abdullah Sami | C16: Al Dammam | D16: 9.661685e+09 | E16: =B16&"@Ex.com" -> Abdullah Sami@Ex.com
A17: 16 | B17: Maha Yasin | C17: Makkah | D17: 9665302440 | E17: =B17&"@Ex.com" -> Maha Yasin@Ex.com
A18: 17 | B18: Salman Rashid | C18: Jeddah | D18: 9664576801 | E18: =B18&"@Ex.com" -> Salman Rashid@Ex.com
A19: 18 | B19: Dana Faisal | C19: Riyadh | D19: 9663461201 | E19: =B19&"@Ex.com" -> Dana Faisal@Ex.com
A20: 19 | B20: Ibrahim Tarek | C20: Al Dammam | D20: 9662605575 | E20: =B20&"@Ex.com" -> Ibrahim Tarek@Ex.com
A21: 20 | B21: Noura Majed | C21: Riyadh | D21: 9.661685e+09 | E21: =B21&"@Ex.com" -> Noura Majed@Ex.com
A22: 21 | B22: Hassan Ali | C22: Jeddah | D22: 9665302440 | E22: =B22&"@Ex.com" -> Hassan Ali@Ex.com
A23: 22 | B23: Rania Sultan | C23: Riyadh | D23: 9664576801 | E23: =B23&"@Ex.com" -> Rania Sultan@Ex.com
A24: 23 | B24: Saad Mutlaq | C24: Al Dammam | D24: 9663461201 | E24: =B24&"@Ex.com" -> Saad Mutlaq@Ex.com
A25: 24 | B25: Mona Hisham | C25: Riyadh | D25: 9662605575 | E25: =B25&"@Ex.com" -> Mona Hisham@Ex.com
A26: 25 | B26: Talal Nawaf | C26: Jeddah | D26: 9.661685e+09 | E26: =B26&"@Ex.com" -> Talal Nawaf@Ex.com
A27: 26 | B27: Aya Mahmoud | C27: Riyadh | D27: 9665302440 | E27: =B27&"@Ex.com" -> Aya Mahmoud@Ex.com
A28: 27 | B28: Zaid Omar | C28: Al Dammam | D28: 9664576801 | E28: =B28&"@Ex.com" -> Zaid Omar@Ex.com
A29: 28 | B29: Laila Qasim | C29: Riyadh | D29: 9663461201 | E29: =B29&"@Ex.com" -> Laila Qasim@Ex.com
A30: 29 | B30: Fahad Turki | C30: Jeddah | D30: 9662605575 | E30: =B30&"@Ex.com" -> Fahad Turki@Ex.com
A31: 30 | B31: Bushra Amin | C31: Riyadh | D31: 9.661685e+09 | E31: =B31&"@Ex.com" -> Bushra Amin@Ex.com
A32: 31 | B32: Mohammed Aziz | C32: Al Dammam | D32: 9665302440 | E32: =B32&"@Ex.com" -> Mohammed Aziz@Ex.com
A33: 32 | B33: Rana Bilal | C33: Riyadh | D33: 9664576801 | E33: =B33&"@Ex.com" -> Rana Bilal@Ex.com
A34: 33 | B34: Nawaf Abdullah | C34: Riyadh | D34: 9663461201 | E34: =B34&"@Ex.com" -> Nawaf Abdullah@Ex.com
A35: 34 | B35: Fatimah Kareem | C35: Riyadh | D35: 9662605575 | E35: =B35&"@Ex.com" -> Fatimah Kareem@Ex.com
A36: 35 | B36: Bandar Saleh | C36: Al Dammam | D36: 9.661685e+09 | E36: =B36&"@Ex.com" -> Bandar Saleh@Ex.com
A37: 36 | B37: Eman Samir | C37: Makkah | D37: 9665302440 | E37: =B37&"@Ex.com" -> Eman Samir@Ex.com
A38: 37 | B38: Abdulaziz Khalaf | C38: Jeddah | D38: 9664576801 | E38: =B38&"@Ex.com" -> Abdulaziz Khalaf@Ex.com
A39: 38 | B39: Mariam Anwar | C39: Riyadh | D39: 9663461201 | E39: =B39&"@Ex.com" -> Mariam Anwar@Ex.com
A40: 39 | B40: Osama Jamal | C40: Al Dammam | D40: 9662605575 | E40: =B40&"@Ex.com" -> Osama Jamal@Ex.com
...

Sheet Products
A1: Prodct_ID | B1: Product_Name | C1: Brand | D1: Category | E1: Price
A2: 100 | B2: SteelSeries Arctis 7 | C2: SteelSeries | D2: Gaming Headset | E2: 1000
A3: 101 | B3: HyperX Cloud II | C3: HyperX | D3: Gaming Headset | E3: 1400
A4: 102 | B4: Corsair HS50 Pro | C4: Corsair | D4: Gaming Headset | E4: 1800
A5: 103 | B5: Kayborad_Red_dragon | C5: Red-dragon | D5: Kayboard | E5: 280
A6: 104 | B6: Kayboard_Razer_Tartrus | C6: Razer_Tartrus | D6: Kayboard | E6: 500
A7: 105 | B7: HyperX Cloud Alpha | C7: HyperX | D7: Gaming Headset | E7: 700
A8: 106 | B8: Mouse_razer basilisk v3 | C8: Mouse_razer | D8: Mouse | E8: 800
A9: 107 | B9: Logitech_G50 | C9: Logitech | D9: Mouse | E9: 250
A10: 108 | B10: Logitech MX Pro Mouse | C10: Logitech | D10: Mouse | E10: 400
A11: 109 | B11: Xbox_One | C11: Xbox_One | D11: Consle | E11: 1600
A12: 110 | B12: XPG Gammix S70 Blade Gen 4 M.2 - 2TB | C12: XPG | D12: Storage | E12: 1200
A13: 111 | B13: XPG GAMMIX S60 Gen 4 NVME M.2 - Black - 512gb | C13: XPG | D13: Storage | E13: 400
... A49: 147 | B49: ASUS TUF Gaming VG27AQ 165Hz | C49: ASUS | D49: Monitor | E49: 1900

Sheet Orders
A1: Order_ID | B1: Order_Date | C1: Customer_ID | D1: Product_ID | E1: Quantity | F1: Unit_Price | G1: Sales | H1: Names | I1: Proudcts
A2: 1001 | B2: 45901 | C2: 1 | D2: 142 | E2: 1 | F2: =_xlfn.XLOOKUP(D2, Products!A:A,Products!E:E, ) -> 500 | G2: =E2 *F2 -> 500 | H2: =_xlfn.XLOOKUP(C2,Customers!A:A,Customers!B:B) -> Mohammed Ali | I2: =_xlfn.XLOOKUP(D2,Products!A:A,Products!B:B) -> Apple Magic Keyboard
A3: 1002 | B3: 45902 | C3: 2 | D3: 112 | E3: 1 | F3: =_xlfn.XLOOKUP(D3, Products!A:A,Products!E:E, ) -> 650 | G3: =E3 *F3 -> 650 | H3: =_xlfn.XLOOKUP(C3,Customers!A:A,Customers!B:B) -> Mona Salah | I3: =_xlfn.XLOOKUP(D3,Products!A:A,Products!B:B) -> Crucial E100 Gen4 NVMe M.2 - Black - 1TB
A4: 1003 | B4: 45902 | C4: 2 | D4: 106 | E4: 2 | F4: =_xlfn.XLOOKUP(D4, Products!A:A,Products!E:E, ) -> 800 | G4: =E4 *F4 -> 1600 | H4: =_xlfn.XLOOKUP(C4,Customers!A:A,Customers!B:B) -> Mona Salah | I4: =_xlfn.XLOOKUP(D4,Products!A:A,Products!B:B) -> Mouse_razer basilisk v3
A5: 1004 | B5: 45903 | C5: 3 | D5: 108 | E5: 2 | F5: =_xlfn.XLOOKUP(D5, Products!A:A,Products!E:E, ) -> 400 | G5: =E5 *F5 -> 800 | H5: =_xlfn.XLOOKUP(C5,Customers!A:A,Customers!B:B) -> Turky Abdullah | I5: =_xlfn.XLOOKUP(D5,Products!A:A,Products!B:B) -> Logitech MX Pro Mouse
A6: 1005 | B6: 45903 | C6: 4 | D6: 140 | E6: 2 | F6: =_xlfn.XLOOKUP(D6, Products!A:A,Products!E:E, ) -> 500 | G6: =E6 *F6 -> 1000 | H6: =_xlfn.XLOOKUP(C6,Customers!A:A,Customers!B:B) -> Sara Khalid | I6: =_xlfn.XLOOKUP(D6,Products!A:A,Products!B:B) -> WD Black SN850X 1TB
A7: 1006 | B7: 45904 | C7: 5 | D7: 116 | E7: 1 | F7: =_xlfn.XLOOKUP(D7, Products!A:A,Products!E:E, ) -> 2002 | G7: =E7 *F7 -> 2002 | H7: =_xlfn.XLOOKUP(C7,Customers!A:A,Customers!B:B) -> Omar Hassan | I7: =_xlfn.XLOOKUP(D7,Products!A:A,Products!B:B) -> PNY GeForce RTX 5060 Ti ARGB OC Triple Fan
A8: 1007 | B8: 45905 | C8: 6 | D8: 100 | E8: 2 | F8: =_xlfn.XLOOKUP(D8, Products!A:A,Products!E:E, ) -> 1000 | G8: =E8 *F8 -> 2000 | H8: =_xlfn.XLOOKUP(C8,Customers!A:A,Customers!B:B) -> Noor Abdullah | I8: =_xlfn.XLOOKUP(D8,Products!A:A,Products!B:B) -> SteelSeries Arctis 7
A9: 1008 | B9: 45905 | C9: 7 | D9: 120 | E9: 1 | F9: =_xlfn.XLOOKUP(D9, Products!A:A,Products!E:E, ) -> 2000 | G9: =E9 *F9 -> 2000 | H9: =_xlfn.XLOOKUP(C9,Customers!A:A,Customers!B:B) -> Faisal Mohammed | I9: =_xlfn.XLOOKUP(D9,Products!A:A,Products!B:B) -> Intel Core i9-13900 CPU
A10: 1009 | B10: 45905 | C10: 8 | D10: 112 | E10: 1 | F10: =_xlfn.XLOOKUP(D10, Products!A:A,Products!E:E, ) -> 650 | G10: =E10 *F10 -> 650 | H10: =_xlfn.XLOOKUP(C10,Customers!A:A,Customers!B:B) -> Aisha Saeed | I10: =_xlfn.XLOOKUP(D10,Products!A:A,Products!B:B) -> Crucial E100 Gen4 NVMe M.2 - Black - 1TB
A11: 1010 | B11: 45906 | C11: 1 | D11: 116 | E11: 1 | F11: =_xlfn.XLOOKUP(D11, Products!A:A,Products!E:E, ) -> 2002 | G11: =E11 *F11 -> 2002 | H11: =_xlfn.XLOOKUP(C11,Customers!A:A,Customers!B:B) -> Mohammed Ali | I11: =_xlfn.XLOOKUP(D11,Products!A:A,Products!B:B) -> PNY GeForce RTX 5060 Ti ARGB OC Triple Fan
A12: 1011 | B12: 45907 | C12: 2 | D12: 103 | E12: 2 | F12: =_xlfn.XLOOKUP(D12, Products!A:A,Products!E:E, ) -> 280 | G12: =E12 *F12 -> 560 | H12: =_xlfn.XLOOKUP(C12,Customers!A:A,Customers!B:B) -> Mona Salah | I12: =_xlfn.XLOOKUP(D12,Products!A:A,Products!B:B) -> Kayborad_Red_dragon
A13: 1012 | B13: 45908 | C13: 3 | D13: 119 | E13: 1 | F13: =_xlfn.XLOOKUP(D13, Products!A:A,Products!E:E, ) -> 1400 | G13: =E13 *F13 -> 1400 | H13: =_xlfn.XLOOKUP(C13,Customers!A:A,Customers!B:B) -> Turky Abdullah | I13: =_xlfn.XLOOKUP(D13,Products!A:A,Products!B:B) -> Intel Core i7-13700 CPU
... A347: 1346 | B347: 46021 | C347: 150 | D347: 130 | E347: 3 | F347: =_xlfn.XLOOKUP(D347, Products!A:A,Products!E:E, ) -> 2250 | G347: =E347 *F347 -> 6750 | H347: =_xlfn.XLOOKUP(C347,Customers!A:A,Customers!B:B) -> Omar Rashid | I347: =_xlfn.XLOOKUP(D347,Products!A:A,Products!B:B) -> MSI RTX 4070 Ti Super Gaming X

Sheet Key_Metrics
A1: Key Performance Metrics - Q4 2024
A2: REVENUE ANALYSIS
A3: Total Revenue | B3: =SUM(Table3[Sales]) -> 622458.24
A4: Avarage Order | B4: =B3/COUNTA(Orders!A:A)-1 -> 1792.8278
A5: Higest order | B5: =MAX(Table3[Sales]) -> 7200
A6: CUSTOMER METRICS
A7: Total Customers | B7: =COUNTA(_xlfn.UNIQUE(Orders!C:C)) -> 150
A8: Orders per Customer | B8: =COUNTA(Key_Metrics!A:A,B7) -> 14
A9: MONTHLY PERFORMANCE
A10: September | B10: =SUMIFS(Orders!G:G, Orders!B:B, ">="&DATE(2025,9,1), Orders!B:B, "<"&DATE(2025,10,1)) -> 50624
A11: October | B11: =SUMIFS(Orders!G:G,Orders!B:B,">="&DATE(2025,10,1),Orders!B:B,"<"&DATE(2025,11,1)) -> 119144
A12: November | B12: =SUMIFS(Orders!G:G,Orders!B:B,">="&DATE(2025,11,1),Orders!B:B,"<"&DATE(2025,12,1)) -> 147332
A13: December | B13: =SUMIFS(Orders!G:G,Orders!B:B,">="&DATE(2025,12,1),Orders!B:B,"<"&DATE(2026,1,1)) -> 305358.24

Sheet Calculations
E1: Brand | F1: Sum of Sales | G1: Products | H1: Sum of Sales | I1: Customers | J1: Sum of Sales | K1: Months | L1: Sum of Sales | M1: Category | N1: Sum of Sales | O1: City | P1: Sum of Sales
E2: AMD | F2: 84649.091 | G2: AMD Ryzen 9 7900x CPU | H2: 20749.091 | I2: Mona Hisham | J2: 17700 | K2: Sep | L2: 50624 | M2: Motherboard | N2: 3900 | O2: Al Dammam | P2: 149306.42
E3: Apple | F3: 6000 | G3: Dell UltraSharp U2723QE Monitor | H3: 20800 | I3: Nada Refaat | J3: 13500 | K3: Oct | L3: 119144 | M3: RAM | N3: 17700 | O3: Jeddah | P3: 147152.18
E4: ASUS | F4: 26700 | G4: ASUS TUF Gaming VG27AQ 165Hz | H4: 22800 | I4: Majed Abdullah | J4: 13100 | K4: Nov | L4: 147332 | M4: Kayboard | N4: 26300 | O4: Makkah | P4: 119258.55
E5: Corsair | F5: 24600 | G5: Sapphire Nitro+ RX 7900 XTX | H5: 23800 | I5: Mona Salah | J5: 13010 | K5: Dec | L5: 305358.24 | M5: Consle | N5: 30300 | O5: Riyadh | P5: 206741.09 | S5: Orders | T5: Sum of Sales
E6: Crucial | F6: 9463.0303 | G6: Intel Core i9-13900 CPU | H6: 24000 | I6: Omar Hassan | J6: 11502 | K6: Grand Total | L6: 622458.24 | M6: Mouse | N6: 32550 | O6: Grand Total | P6: 622458.24 | S6: 346 | T6: 622458.24
E7: Dell | F7: 20800 | G7: Intel Core Ultra 7 265KF Tray CPU | H7: 24000 | I7: Dana Faisal | J7: 10908.485 | M7: Gaming Headset | N7: 59300
E8: HP | F8: 5600 | G8: MSI RTX 4070 Ti Super Gaming X | H8: 29250 | I8: Shatha Omar | J8: 10000 | M8: Monitor | N8: 68938.182 | S8: =GETPIVOTDATA("[Measures].[Sum of Sales]",$O$1) -> 622458.24 | T8: =S6 -> 346
E9: HyperX | F9: 25900 | G9: Sapphire PULSE AMD Radeon RX 9070 XT 16GB GPU | H9: 33000 | I9: Youssef Nasser | J9: 9900 | M9: Storage | N9: 72276.97
E10: Intel | F10: 79200 | G10: AMD Ryzen 9 9950X3D CPU | H10: 36300 | I10: Nawaf Abdullah | J10: 9400 | M10: GPU | N10: 147344
E11: Kingston_FURY | F11: 7500 | G11: Palit GeForce RTX 5060 Infinity | H11: 39600 | I11: Reem Adel | J11: 9150 | M11: CPU | N11: 163849.09
E12: LG | F12: 11738.182 | G12: Grand Total | H12: 274299.09 | I12: Fahad Turki | J12: 9100 | M12: Grand Total | N12: 622458.24 | S12: =T6/S6 -> 1799.0123
E13: Logitech | F13: 10250 | I13: Hanan Adel | J13: 8480
E14: Mouse_razer | F14: 11200 | I14: Turky Abdullah | J14: 8400
E15: MSI | F15: 36930 | I15: Yazan Kareem | J15: 8362
E16: Palit | F16: 39600 | I16: Noura Majed | J16: 8349.0909
E17: PlayStation-5 | F17: 5400 | I17: Bilal Farhan | J17: 8300
E18: PNY | F18: 14014 | I18: Faisal Mohammed | J18: 8240
E19: Razer | F19: 5500 | I19: Salma Yousif | J19: 8100
E20: Razer_Tartrus | F20: 10500 | I20: Farah Issa | J20: 8100
E21: Red-dragon | F21: 9800 | I21: Sahar Jibril | J21: 8100
E22: Samsung | F22: 33913.939 | I22: Muneer Sami | J22: 8000
E23: Sapphire | F23: 56800 | I23: Haytham Rami | J23: 7800
E24: Seagate | F24: 3600 | I24: Muteb Khalid | J24: 7600
... E30: Grand Total | F30: 622458.24 | I30: Abdullah Sami | J30: 7260
I31: Ndeem Ali | J31: 7200
I32: Turky Ali | J32: 7200
I33: Maha Yasin | J33: 7000
I34: Amal Fouad | J34: 6800
I35: Omar Rashid | J35: 6750
I36: Sara Khalid | J36: 6650
I37: Ikram Yusuf | J37: 6600
I38: Rania Sultan | J38: 6600
I39: Rima Ziad | J39: 6600
I40: Rawan Mazen | J40: 6500
I41: Aisha Saeed | J41: 6400
I42: Sultan Fahd | J42: 6400
... I147: Grand Total | J147: 622458.24

Sheet Dashboard
T27: Riyadh Leads 33% market share 111 orders
I31: High Loyalty 135% repeat rate Customers return often
A33: TOP 10 Customers | B33: Sales
A34: Mona Hisham | B34: 17700
A35: Nada Refaat | B35: 13500
A36: Majed Abdullah | B36: 13100
A37: Mona Salah | B37: 13010
A38: Omar Hassan | B38: 11502
A39: Dana Faisal | B39: 10908.485
A40: Shatha Omar | B40: 10000
A41: Youssef Nasser | B41: 9900
A42: Nawaf Abdullah | B42: 9400
A43: Reem Adel | B43: 9150
A44: Grand Total | B44: 118170.48
